<?xml version="1.0" ?>
<!-- =================================================================================== -->
<!-- |    This document was autogenerated by xacro from omnigrasper_arm_only.urdf.xacro | -->
<!-- |    EDITING THIS FILE BY HAND IS NOT RECOMMENDED                                 | -->
<!-- =================================================================================== -->
<robot name="omnigrasper" xmlns:xacro="http://ros.org/wiki/xacro">
  <!-- end of arm links/joints -->
  <material name="omni/Blue">
    <color rgba="0 0 0.8 1"/>
  </material>
  <material name="omni/Red">
    <color rgba="1 0 0 1"/>
  </material>
  <material name="omni/Green">
    <color rgba="0 1 0 1"/>
  </material>
  <material name="omni/Yellow">
    <color rgba="1 1 0 1"/>
  </material>
  <material name="omni/LightGrey">
    <color rgba="0.6 0.6 0.6 1"/>
  </material>
  <material name="omni/DarkGrey">
    <color rgba="0.4 0.4 0.4 1"/>
  </material>
  <!-- Now we can start using the macros xacro:included above to define the actual omnipointer -->
  <!-- The first use of a macro.  This one was defined in youbot_base/base.urdf.xacro above.
       A macro like this will expand to a set of link and joint definitions, and to additional
       Gazebo-related extensions (sensor plugins, etc).  The macro takes an argument, name,
       that equals "base", and uses it to generate names for its component links and joints
       (e.g., base_link).  The xacro:included origin block is also an argument to the macro.  By convention,
       the origin block defines where the component is w.r.t its parent (in this case the parent
       is the world frame). For more, see http://www.ros.org/wiki/xacro -->
  <!-- foot for arm-->
  <link name="base_link">
    <inertial>
      <origin rpy="0 0 0" xyz="0 0 0"/>
      <mass value="10.0"/>
      <inertia ixx="0.1" ixy="0" ixz="0" iyy="0.1" iyz="0" izz="0.1"/>
    </inertial>
  </link>
  <joint name="base_link_arm_base" type="fixed">
    <parent link="base_link"/>
    <child link="arm_base"/>
    <origin rpy="0 0 0" xyz="0 0 0.004"/>
  </joint>
  <link name="arm_base"/>
  <joint name="arm_base_arm_0" type="fixed">
    <parent link="arm_base"/>
    <child link="arm_0"/>
    <origin xyz="0 0 0.141"/>
  </joint>
  <link name="arm_0">
    <!-- L54-30-S500 -->
    <visual>
      <origin rpy="1.57079632679 0 0" xyz="0 0 -0.141"/>
      <geometry>
        <mesh filename="package://omni_description/stl/L54-30-S500-R.STL" scale="0.001 0.001 0.001"/>
      </geometry>
      <material name="omni/Blue"/>
    </visual>
    <collision>
      <origin rpy="0 0 0" xyz="0 0 -0.087"/>
      <geometry>
        <box size="0.054 0.054 0.108"/>
      </geometry>
    </collision>
  </link>
  <joint name="arm_0_1" type="revolute">
    <parent link="arm_0"/>
    <child link="arm_1"/>
    <limit effort="2.5" lower="-3.14159265359" upper="3.14159265359" velocity="3.00545697193"/>
    <safety_controller k_position="3" k_velocity="1000" soft_lower_limit="-3.14159265359" soft_upper_limit="3.14159265359"/>
    <origin rpy="0 0 0" xyz="0 0 0"/>
    <axis xyz="0 0 1"/>
  </joint>
  <link name="arm_1">
    <!-- For Box Collision Intertial -->
    <collision>
      <origin rpy="0 0 0" xyz="0 0 0"/>
      <geometry>
        <box size="0.054 0.132 0.054"/>
      </geometry>
    </collision>
    <inertial>
      <!-- center of mass -->
      <origin rpy="0 0 0" xyz="0 0 0"/>
      <mass value="0.855"/>
      <!-- box inertia: 1/12*m(y^2+z^2), ... -->
      <inertia ixx="0.001449225" ixy="0" ixz="0" iyy="0.00041553" iyz="0" izz="0.001449225"/>
    </inertial>
    <!-- H54-200-S500 -->
    <visual>
      <origin xyz="0 -0.066 0"/>
      <geometry>
        <mesh filename="package://omni_description/stl/H54-200-S500-R.STL" scale="0.001 0.001 0.001"/>
      </geometry>
      <material name="omni/Red"/>
    </visual>
    <!-- FRP54-A110 -->
    <visual>
      <origin rpy="1.57079632679 0 0" xyz="0 0 -0.033"/>
      <geometry>
        <mesh filename="package://omni_description/stl/FRP54-A110.STL" scale="0.001 0.001 0.001"/>
      </geometry>
      <material name="omni/Red"/>
    </visual>
  </link>
  <joint name="arm_1_2" type="revolute">
    <parent link="arm_1"/>
    <child link="arm_2"/>
    <limit effort="44.7" lower="-1.80159265359" upper="1.79840734641" velocity="3.46622389446"/>
    <safety_controller k_position="3" k_velocity="1000" soft_lower_limit="-1.80159265359" soft_upper_limit="1.79840734641"/>
    <origin rpy="1.57079632679 -1.57079632679 0" xyz="0 0 0"/>
    <axis xyz="0 0 1"/>
  </joint>
  <link name="arm_2">
    <!-- For Box Visual Collision Intertial -->
    <visual>
      <origin rpy="0 0 0" xyz="0.141 0 0"/>
      <geometry name="profile_2">
        <box size="0.18 0.04 0.04"/>
      </geometry>
      <material name="omni/Green"/>
    </visual>
    <collision>
      <origin rpy="0 0 0" xyz="0.141 0 0"/>
      <geometry>
        <box size="0.18 0.04 0.04"/>
      </geometry>
    </collision>
    <inertial>
      <!-- center of mass -->
      <origin rpy="0 0 0" xyz="0.141 0 0"/>
      <mass value="0.2484"/>
      <!-- box inertia: 1/12*m(y^2+z^2), ... -->
      <inertia ixx="6.624e-05" ixy="0" ixz="0" iyy="0.0007038" iyz="0" izz="0.0007038"/>
    </inertial>
    <!-- FRP54-H220 -->
    <visual>
      <origin rpy="0 3.14159265359 -1.57079632679" xyz="0 0 0"/>
      <geometry>
        <mesh filename="package://omni_description/stl/FRP54-H220.STL" scale="0.001 0.001 0.001"/>
      </geometry>
      <material name="omni/Green"/>
    </visual>
    <!-- FRP54-A110 -->
    <visual>
      <origin rpy="0 0 -1.57079632679" xyz="0.231 0 0"/>
      <geometry>
        <mesh filename="package://omni_description/stl/FRP54-A110.STL" scale="0.001 0.001 0.001"/>
      </geometry>
      <material name="omni/Green"/>
    </visual>
  </link>
  <joint name="arm_2_sub" type="fixed">
    <parent link="arm_2"/>
    <child link="arm_2_sub"/>
    <origin xyz="0 0 0"/>
  </joint>
  <link name="arm_2_sub">
    <!-- L5450-S500 -->
    -
            
    <!-- For Box Collision Intertial -->
    <collision>
      <origin rpy="0 0 0" xyz="0.264 0 0"/>
      <geometry>
        <box size="0.054 0.054 0.114"/>
      </geometry>
    </collision>
    <inertial>
      <!-- center of mass -->
      <origin rpy="0 0 0" xyz="0.264 0 0"/>
      <mass value="0.662"/>
      <!-- box inertia: 1/12*m(y^2+z^2), ... -->
      <inertia ixx="0.000877812" ixy="0" ixz="0" iyy="0.000877812" iyz="0" izz="0.000321732"/>
    </inertial>
    <visual>
      <origin rpy="-1.57079632679 0 0" xyz="0.264 0 0.057"/>
      <geometry>
        <mesh filename="package://omni_description/stl/L54-50-S500-R.STL" scale="0.001 0.001 0.001"/>
      </geometry>
      <material name="omni/Green"/>
    </visual>
  </link>
  <joint name="arm_2_3" type="revolute">
    <parent link="arm_2"/>
    <child link="arm_3"/>
    <limit effort="14" lower="-1.82159265359" upper="1.25840734641" velocity="1.67551608191"/>
    <safety_controller k_position="3" k_velocity="1000" soft_lower_limit="-1.82159265359" soft_upper_limit="1.35840734641"/>
    <origin rpy="0 0 -1.57079632679" xyz="0.264 0 0"/>
    <axis xyz="0 0 1"/>
  </joint>
  <link name="arm_3">
    <!-- For Box Visual Collision Intertial -->
    <visual>
      <origin rpy="0 0 0" xyz="0 0.081 0"/>
      <geometry name="profile_3">
        <box size="0.04 0.06 0.04"/>
      </geometry>
      <material name="omni/Yellow"/>
    </visual>
    <collision>
      <origin rpy="0 0 0" xyz="0 0.081 0"/>
      <geometry>
        <box size="0.04 0.06 0.04"/>
      </geometry>
    </collision>
    <inertial>
      <!-- center of mass -->
      <origin rpy="0 0 0" xyz="0 0.081 0"/>
      <mass value="0.0828"/>
      <!-- box inertia: 1/12*m(y^2+z^2), ... -->
      <inertia ixx="3.588e-05" ixy="0" ixz="0" iyy="2.208e-05" iyz="0" izz="3.588e-05"/>
    </inertial>
    <!-- FRP54-H120 -->
    <visual>
      <origin rpy="0 3.14159265359 0" xyz="0 0 0"/>
      <geometry>
        <mesh filename="package://omni_description/stl/FRP54-H120.STL" scale="0.001 0.001 0.001"/>
      </geometry>
      <material name="omni/Yellow"/>
    </visual>
    <!-- FRP54-A110 -->
    <visual>
      <origin rpy="0 0 0" xyz="0 0.111 0"/>
      <geometry>
        <mesh filename="package://omni_description/stl/FRP54-A110.STL" scale="0.001 0.001 0.001"/>
      </geometry>
      <material name="omni/Yellow"/>
    </visual>
  </link>
  <joint name="arm_3_sub" type="fixed">
    <parent link="arm_3"/>
    <child link="arm_3_sub"/>
    <origin xyz="0 0 0"/>
  </joint>
  <link name="arm_3_sub">
    <!-- For Box Collision Intertial -->
    <collision>
      <origin rpy="0 0 0" xyz="0 0.171 0"/>
      <geometry>
        <box size="0.054 0.108 0.054"/>
      </geometry>
    </collision>
    <inertial>
      <!-- center of mass -->
      <origin rpy="0 0 0" xyz="0 0.171 0"/>
      <mass value="0.612"/>
      <!-- box inertia: 1/12*m(y^2+z^2), ... -->
      <inertia ixx="0.00074358" ixy="0" ixz="0" iyy="0.000297432" iyz="0" izz="0.00074358"/>
    </inertial>
    <visual>
      <origin rpy="0 -3.14159265359 0" xyz="0 0.117 0"/>
      <geometry>
        <mesh filename="package://omni_description/stl/L54-30-S500-R.STL" scale="0.001 0.001 0.001"/>
      </geometry>
      <material name="omni/Yellow"/>
    </visual>
  </link>
  <joint name="arm_3_4" type="revolute">
    <parent link="arm_3"/>
    <child link="arm_4"/>
    <limit effort="2.5" lower="-3.14159265359" upper="3.14159265359" velocity="3.00545697193"/>
    <safety_controller k_position="3" k_velocity="1000" soft_lower_limit="-3.14159265359" soft_upper_limit="3.14159265359"/>
    <origin rpy="-1.57079632679 0 0" xyz="0 0.252 0"/>
    <axis xyz="0 0 1"/>
  </joint>
  <link name="arm_4">
    <!-- For Box Collision Intertial -->
    <collision>
      <origin rpy="0 0 0" xyz="0 0.006 0"/>
      <geometry>
        <box size="0.042 0.072 0.042"/>
      </geometry>
    </collision>
    <inertial>
      <!-- center of mass -->
      <origin rpy="0 0 0" xyz="0 0.006 0"/>
      <mass value="0.257"/>
      <!-- box inertia: 1/12*m(y^2+z^2), ... -->
      <inertia ixx="0.000148803" ixy="0" ixz="0" iyy="7.5558e-05" iyz="0" izz="0.000148803"/>
    </inertial>
    <visual>
      <origin rpy="0 0 0" xyz="0 -0.03 0"/>
      <geometry>
        <mesh filename="package://omni_description/stl/L42-10-S300-R.STL" scale="0.001 0.001 0.001"/>
      </geometry>
      <material name="omni/DarkGrey"/>
    </visual>
    <!-- FRP42-A110 -->
    <visual>
      <origin rpy="1.57079632679 0 0" xyz="0 0 -0.027"/>
      <geometry>
        <mesh filename="package://omni_description/stl/FRP42-A110.STL" scale="0.001 0.001 0.001"/>
      </geometry>
      <material name="omni/DarkGrey"/>
    </visual>
  </link>
  <joint name="arm_4_5" type="revolute">
    <parent link="arm_4"/>
    <child link="arm_5"/>
    <limit effort="1.2" lower="-1.57079632679" upper="1.57079632679" velocity="3.11017672705"/>
    <safety_controller k_position="2" k_velocity="1000" soft_lower_limit="-1.57079632679" soft_upper_limit="1.57079632679"/>
    <origin rpy="1.57079632679 0 0" xyz="0 0 0"/>
    <axis xyz="0 0 1"/>
  </joint>
  <link name="arm_5">
    <!-- For Box Collision Intertial -->
    <collision>
      <origin rpy="0 0 0" xyz="0 0.039 -0.006"/>
      <geometry>
        <box size="0.042 0.006 0.082"/>
      </geometry>
    </collision>
    <inertial>
      <!-- center of mass -->
      <origin rpy="0 0 0" xyz="0 0.039 -0.006"/>
      <mass value="0.0857"/>
      <!-- box inertia: 1/12*m(y^2+z^2), ... -->
      <inertia ixx="4.82776666667e-05" ixy="0" ixz="0" iyy="6.06184666667e-05" iyz="0" izz="1.2855e-05"/>
    </inertial>
    <!-- FRP42-H120 -->
    <visual>
      <origin rpy="0 0 0" xyz="0 0 -0.006"/>
      <geometry>
        <mesh filename="package://omni_description/stl/FRP42-H120.STL" scale="0.001 0.001 0.001"/>
      </geometry>
      <material name="omni/Blue"/>
    </visual>
  </link>
  <joint name="arm_5_end" type="fixed">
    <parent link="arm_5"/>
    <child link="arm_link"/>
    <origin xyz="0 0.039 -0.006"/>
  </joint>
  <link name="arm_link"/>
  <joint name="arm_end_versaball" type="fixed">
    <parent link="arm_link"/>
    <child link="versaball_link"/>
    <origin rpy="-1.57079632679 0 0" xyz="0 0.081 0"/>
  </joint>
  <link name="versaball_link"/>
</robot>

