<?xml version="1.0" ?>
<!-- =================================================================================== -->
<!-- |    This document was autogenerated by xacro from omnigrasper.urdf.xacro         | -->
<!-- |    EDITING THIS FILE BY HAND IS NOT RECOMMENDED                                 | -->
<!-- =================================================================================== -->
<robot name="omnigrasper" xmlns:controller="http://playerstage.sourceforge.net/gazebo/xmlschema/#controller" xmlns:interface="http://playerstage.sourceforge.net/gazebo/xmlschema/#interface" xmlns:sensor="http://playerstage.sourceforge.net/gazebo/xmlschema/#sensor" xmlns:xacro="http://ros.org/wiki/xacro">
  <!-- end of arm links/joints -->
  <material name="youBot/Orange">
    <color rgba="1.0 0.4 0.0 1.0"/>
  </material>
  <material name="youBot/Grey">
    <color rgba="0.7 0.7 0.7 1.0"/>
  </material>
  <material name="youBot/DarkGrey">
    <color rgba="0.3 0.3 0.3 1.0"/>
  </material>
  <material name="youBot/White">
    <color rgba="1.0 1.0 1.0 1.0"/>
  </material>
  <material name="youBot/Black">
    <color rgba="0.0 0.0 0.0 1.0"/>
  </material>
  <material name="youBot/Red">
    <color rgba="1.0 0.0 0.0 1.0"/>
  </material>
  <material name="youBot/Green">
    <color rgba="0.0 1.0 0.0 1.0"/>
  </material>
  <material name="youBot/Blue">
    <color rgba="0.0 0.0 0.8 1.0"/>
  </material>
  <material name="youBot/LightGrey">
    <color rgba="0.82 0.82 0.82 1.0"/>
  </material>
  <material name="omni/Blue">
    <color rgba="0 0 0.8 1"/>
  </material>
  <material name="omni/Red">
    <color rgba="1 0 0 1"/>
  </material>
  <material name="omni/Green">
    <color rgba="0 1 0 1"/>
  </material>
  <material name="omni/Yellow">
    <color rgba="1 1 0 1"/>
  </material>
  <material name="omni/LightGrey">
    <color rgba="0.6 0.6 0.6 1"/>
  </material>
  <material name="omni/DarkGrey">
    <color rgba="0.4 0.4 0.4 1"/>
  </material>
  <!-- Now we can start using the macros xacro:included above to define the actual robot -->
  <link name="base_footprint">
    <inertial>
      <mass value="0.1"/>
      <origin rpy="0 0 0" xyz="0 0 -0.05"/>
      <inertia ixx="1.0" ixy="0.0" ixz="0.0" iyy="1.0" iyz="0.0" izz="1.0"/>
    </inertial>
    <visual>
      <origin rpy="0 0 0" xyz="0 0 0"/>
      <geometry>
        <box size="0.001 0.001 0.001"/>
      </geometry>
      <material name="youBot/Red"/>
    </visual>
    <collision>
      <origin rpy="0 0 0" xyz="0 0 -0.05"/>
      <geometry>
        <box size="0.001 0.001 0.001"/>
      </geometry>
    </collision>
  </link>
  <joint name="base_footprint_joint" type="fixed">
    <origin rpy="0 0 0" xyz="0 0 0"/>
    <child link="base_link"/>
    <parent link="base_footprint"/>
  </joint>
  <link name="base_link">
    <inertial>
      <mass value="22.0"/>
      <origin xyz="0 0 0"/>
      <inertia ixx="5.652232699207" ixy="-0.009719934438" ixz="1.293988226423" iyy="5.669473158652" iyz="-0.007379583694" izz="3.683196351726"/>
    </inertial>
    <visual>
      <origin rpy="0 0 0" xyz="0 0 0"/>
      <geometry>
        <mesh filename="package://youbot_description/meshes/youbot_base/base.dae"/>
      </geometry>
      <material name="youBot/DarkGrey"/>
    </visual>
    <collision>
      <origin rpy="0 0 0" xyz="0 0 0"/>
      <geometry>
        <!--<box size="${base_size_x} ${base_size_y} ${base_size_z}" />-->
        <mesh filename="package://youbot_description/meshes/youbot_base/base_convex.dae"/>
      </geometry>
    </collision>
  </link>
  <!-- front left wheel -->
  <joint name="caster_joint_fl" type="continuous">
    <origin rpy="0 0 0" xyz="0.228 0.158 -0.034"/>
    <axis xyz="0 0 1"/>
    <limit effort="30" velocity="10"/>
    <dynamics damping="1.0" friction="1.0"/>
    <safety_controller k_velocity="10.0"/>
    <parent link="base_link"/>
    <child link="caster_link_fl"/>
  </joint>
  <link name="caster_link_fl">
    <inertial>
      <mass value="0.1"/>
      <origin xyz="0 0 0"/>
      <inertia ixx="0.012411765597" ixy="-0.000711733678" ixz="0.00050272983" iyy="0.015218160428" iyz="-0.000004273467" izz="0.011763977943"/>
    </inertial>
  </link>
  <joint name="wheel_joint_fl" type="continuous">
    <axis xyz="0 1 0"/>
    <limit effort="30" velocity="10"/>
    <origin rpy="0 0 0" xyz="0.0 0.0 0.0"/>
    <parent link="caster_link_fl"/>
    <dynamics damping="1.0" friction="1.0"/>
    <safety_controller k_velocity="10.0"/>
    <child link="wheel_link_fl"/>
  </joint>
  <link name="wheel_link_fl">
    <inertial>
      <mass value="1.4"/>
      <origin xyz="0 0 0"/>
      <inertia ixx="0.012411765597" ixy="-0.000711733678" ixz="0.00050272983" iyy="0.015218160428" iyz="-0.000004273467" izz="0.011763977943"/>
    </inertial>
    <visual>
      <origin rpy="0 0 0" xyz="0 0 0"/>
      <!--<mesh filename="package://youbot_description/meshes/youbot_base/youbot_wheel.stl" />-->
      <geometry>
        <sphere radius="0.0475"/>
      </geometry>
      <material name="youBot/Orange"/>
    </visual>
    <collision>
      <origin rpy="1.57079632679 0 0" xyz="0 0 0"/>
      <geometry>
        <cylinder length="0.0475" radius="0.0475"/>
      </geometry>
    </collision>
  </link>
  <!-- front right wheel -->
  <joint name="caster_joint_fr" type="continuous">
    <origin rpy="0 0 0" xyz="0.228 -0.158 -0.034"/>
    <axis xyz="0 0 1"/>
    <limit effort="30" velocity="10"/>
    <dynamics damping="1.0" friction="1.0"/>
    <safety_controller k_velocity="10.0"/>
    <parent link="base_link"/>
    <child link="caster_link_fr"/>
  </joint>
  <link name="caster_link_fr">
    <inertial>
      <mass value="0.1"/>
      <origin xyz="0 0 0"/>
      <inertia ixx="0.012411765597" ixy="-0.000711733678" ixz="0.00050272983" iyy="0.015218160428" iyz="-0.000004273467" izz="0.011763977943"/>
    </inertial>
  </link>
  <joint name="wheel_joint_fr" type="continuous">
    <axis xyz="0 1 0"/>
    <limit effort="30" velocity="10"/>
    <dynamics damping="1.0" friction="1.0"/>
    <safety_controller k_velocity="10.0"/>
    <origin rpy="0 0 0" xyz="0.0 0.0 0.0"/>
    <parent link="caster_link_fr"/>
    <child link="wheel_link_fr"/>
  </joint>
  <link name="wheel_link_fr">
    <inertial>
      <mass value="1.4"/>
      <origin xyz="0 0 0"/>
      <inertia ixx="0.012411765597" ixy="-0.000711733678" ixz="0.00050272983" iyy="0.015218160428" iyz="-0.000004273467" izz="0.011763977943"/>
    </inertial>
    <visual>
      <origin rpy="0 0 0" xyz="0 0 0"/>
      <geometry>
        <!--<mesh filename="package://youbot_description/meshes/youbot_base/youbot_wheel.stl" />-->
        <sphere radius="0.0475"/>
      </geometry>
      <material name="youBot/Orange"/>
    </visual>
    <collision>
      <origin rpy="1.57079632679 0 0" xyz="0 0 0"/>
      <geometry>
        <cylinder length="0.0475" radius="0.0475"/>
      </geometry>
    </collision>
  </link>
  <!-- back left wheel -->
  <joint name="caster_joint_bl" type="continuous">
    <origin rpy="0 0 0" xyz="-0.228 0.158 -0.034"/>
    <axis xyz="0 0 1"/>
    <limit effort="30" velocity="10"/>
    <dynamics damping="1.0" friction="1.0"/>
    <safety_controller k_velocity="10.0"/>
    <parent link="base_link"/>
    <child link="caster_link_bl"/>
  </joint>
  <link name="caster_link_bl">
    <inertial>
      <mass value="0.1"/>
      <origin xyz="0 0 0"/>
      <inertia ixx="0.012411765597" ixy="-0.000711733678" ixz="0.00050272983" iyy="0.015218160428" iyz="-0.000004273467" izz="0.011763977943"/>
    </inertial>
  </link>
  <joint name="wheel_joint_bl" type="continuous">
    <axis xyz="0 1 0"/>
    <limit effort="10" velocity="10"/>
    <limit effort="30" velocity="10"/>
    <dynamics damping="1.0" friction="1.0"/>
    <safety_controller k_velocity="10.0"/>
    <origin rpy="0 0 0" xyz="0.0 0.0 0.0"/>
    <parent link="caster_link_bl"/>
    <child link="wheel_link_bl"/>
  </joint>
  <link name="wheel_link_bl">
    <inertial>
      <mass value="1.4"/>
      <origin xyz="0 0 0"/>
      <inertia ixx="0.012411765597" ixy="-0.000711733678" ixz="0.00050272983" iyy="0.015218160428" iyz="-0.000004273467" izz="0.011763977943"/>
    </inertial>
    <visual>
      <origin rpy="0 0 0" xyz="0 0 0"/>
      <geometry>
        <!--<mesh filename="package://youbot_description/meshes/youbot_base/youbot_wheel.stl" />-->
        <sphere radius="0.0475"/>
      </geometry>
      <material name="youBot/Orange"/>
    </visual>
    <collision>
      <origin rpy="1.57079632679 0 0" xyz="0 0 0"/>
      <geometry>
        <cylinder length="0.0475" radius="0.0475"/>
      </geometry>
    </collision>
  </link>
  <!-- back right wheel -->
  <joint name="caster_joint_br" type="continuous">
    <origin rpy="0 0 0" xyz="-0.228 -0.158 -0.034"/>
    <axis xyz="0 0 1"/>
    <limit effort="30" velocity="10"/>
    <dynamics damping="1.0" friction="1.0"/>
    <safety_controller k_velocity="10.0"/>
    <parent link="base_link"/>
    <child link="caster_link_br"/>
  </joint>
  <link name="caster_link_br">
    <inertial>
      <mass value="0.1"/>
      <origin xyz="0 0 0"/>
      <inertia ixx="0.012411765597" ixy="-0.000711733678" ixz="0.00050272983" iyy="0.015218160428" iyz="-0.000004273467" izz="0.011763977943"/>
    </inertial>
  </link>
  <joint name="wheel_joint_br" type="continuous">
    <axis xyz="0 1 0"/>
    <limit effort="30" velocity="10"/>
    <dynamics damping="1.0" friction="1.0"/>
    <safety_controller k_velocity="10.0"/>
    <origin rpy="0 0 0" xyz="0.0 0.0 0.0"/>
    <parent link="caster_link_br"/>
    <child link="wheel_link_br"/>
  </joint>
  <link name="wheel_link_br">
    <inertial>
      <mass value="1.4"/>
      <origin xyz="0 0 0"/>
      <inertia ixx="0.012411765597" ixy="-0.000711733678" ixz="0.00050272983" iyy="0.015218160428" iyz="-0.000004273467" izz="0.011763977943"/>
    </inertial>
    <visual>
      <origin rpy="0 0 0" xyz="0 0 0"/>
      <geometry>
        <!--<mesh filename="package://youbot_description/meshes/youbot_base/youbot_wheel.stl" />-->
        <sphere radius="0.0475"/>
      </geometry>
      <material name="youBot/Orange"/>
    </visual>
    <collision>
      <origin rpy="1.57079632679 0 0" xyz="0 0 0"/>
      <geometry>
        <cylinder length="0.0475" radius="0.0475"/>
      </geometry>
    </collision>
  </link>
  <gazebo reference="youbot_base">
    </gazebo>
  <!-- front left wheel -->
  <gazebo reference="wheel_link_fl">
    <kp>1000000</kp>
    <kd>100</kd>
  </gazebo>
  <gazebo reference="caster_link_fl">
    </gazebo>
  <!-- front right wheel -->
  <gazebo reference="wheel_link_fr">
    <kp>1000000</kp>
    <kd>100</kd>
  </gazebo>
  <gazebo reference="caster_link_fr">   
    </gazebo>
  <!-- back left wheel -->
  <gazebo reference="wheel_link_bl">
    <kp>1000000</kp>
    <kd>100</kd>
  </gazebo>
  <gazebo reference="caster_link_bl">
    </gazebo>
  <!-- back right wheel -->
  <gazebo reference="wheel_link_br">
    <kp>1000000</kp>
    <kd>100</kd>
  </gazebo>
  <gazebo reference="caster_link_br">
    </gazebo>
  <!-- front left wheel -->
  <transmission name="wheel_trans_fl">
    <type>transmission_interface/SimpleTransmission</type>
    <actuator name="wheel_motor_fl">
      <hardwareInterface>VelocityJointInterface</hardwareInterface>
      <mechanicalReduction>79.2380952381</mechanicalReduction>
    </actuator>
    <joint name="wheel_joint_fl"/>
  </transmission>
  <transmission name="caster_trans_fl">
    <type>transmission_interface/SimpleTransmission</type>
    <actuator name="caster_motor_fl">
      <hardwareInterface>VelocityJointInterface</hardwareInterface>
      <mechanicalReduction>79.2380952381</mechanicalReduction>
    </actuator>
    <joint name="caster_joint_fl"/>
  </transmission>
  <!-- front right wheel -->
  <transmission name="wheel_trans_fr">
    <type>transmission_interface/SimpleTransmission</type>
    <actuator name="wheel_motor_fr">
      <hardwareInterface>VelocityJointInterface</hardwareInterface>
      <mechanicalReduction>79.2380952381</mechanicalReduction>
    </actuator>
    <joint name="wheel_joint_fr"/>
  </transmission>
  <transmission name="caster_trans_fr">
    <type>transmission_interface/SimpleTransmission</type>
    <actuator name="caster_motor_fr">
      <hardwareInterface>VelocityJointInterface</hardwareInterface>
      <mechanicalReduction>79.2380952381</mechanicalReduction>
    </actuator>
    <joint name="caster_joint_fr"/>
  </transmission>
  <!-- back left wheel -->
  <transmission name="wheel_trans_bl">
    <type>transmission_interface/SimpleTransmission</type>
    <actuator name="wheel_motor_bl">
      <hardwareInterface>VelocityJointInterface</hardwareInterface>
      <mechanicalReduction>79.2380952381</mechanicalReduction>
    </actuator>
    <joint name="wheel_joint_bl"/>
  </transmission>
  <transmission name="caster_trans_bl">
    <type>transmission_interface/SimpleTransmission</type>
    <actuator name="caster_motor_bl">
      <hardwareInterface>VelocityJointInterface</hardwareInterface>
      <mechanicalReduction>79.2380952381</mechanicalReduction>
    </actuator>
    <joint name="caster_joint_bl"/>
  </transmission>
  <!-- back right wheel -->
  <transmission name="wheel_trans_br">
    <type>transmission_interface/SimpleTransmission</type>
    <actuator name="wheel_motor_br">
      <hardwareInterface>VelocityJointInterface</hardwareInterface>
      <mechanicalReduction>79.2380952381</mechanicalReduction>
    </actuator>
    <joint name="wheel_joint_br"/>
  </transmission>
  <transmission name="caster_trans_br">
    <type>transmission_interface/SimpleTransmission</type>
    <actuator name="caster_motor_br">
      <hardwareInterface>VelocityJointInterface</hardwareInterface>
      <mechanicalReduction>79.2380952381</mechanicalReduction>
    </actuator>
    <joint name="caster_joint_br"/>
  </transmission>
  <!-- joint between base_link and plate_link -->
  <joint name="plate_joint" type="fixed">
    <origin rpy="0 0 0" xyz="-0.148 0 0.061"/>
    <parent link="base_link"/>
    <child link="plate_link"/>
  </joint>
  <link name="plate_link">
    <visual>
      <origin rpy="0 0 0" xyz="0 0 0.002"/>
      <geometry>
        <box size="0.2 0.2 0.004"/>
      </geometry>
      <material name="omni/DarkGrey"/>
    </visual>
    <collision>
      <origin rpy="0 0 0" xyz="0 0 0.002"/>
      <geometry>
        <box size="0.2 0.2 0.004"/>
      </geometry>
    </collision>
    <inertial>
      <!-- CENTER OF MASS -->
      <origin rpy="0 0 0" xyz="0 0 0.002"/>
      <mass value="0.5"/>
      <!-- box inertia: 1/12*m(y^2+z^2), ... -->
      <inertia ixx="0.00166733333333" ixy="0" ixz="0" iyy="0.00166733333333" iyz="0" izz="0.00333333333333"/>
    </inertial>
  </link>
  <!-- END OF OUR PLATE -->
  <joint name="plate_link_arm_base" type="fixed">
    <parent link="plate_link"/>
    <child link="arm_base"/>
    <origin rpy="0 0 0" xyz="0 0 0.004"/>
  </joint>
  <link name="arm_base"/>
  <joint name="arm_base_arm_0" type="fixed">
    <parent link="arm_base"/>
    <child link="arm_0"/>
    <origin xyz="0 0 0.141"/>
  </joint>
  <link name="arm_0">
    <!-- L54-30-S500 -->
    <visual>
      <origin rpy="1.57079632679 0 0" xyz="0 0 -0.141"/>
      <geometry>
        <mesh filename="package://omni_description/stl/L54-30-S500-R.STL" scale="0.001 0.001 0.001"/>
      </geometry>
      <material name="omni/Blue"/>
    </visual>
    <collision>
      <origin rpy="0 0 0" xyz="0 0 -0.087"/>
      <geometry>
        <box size="0.054 0.054 0.108"/>
      </geometry>
    </collision>
  </link>
  <joint name="arm_0_1" type="revolute">
    <parent link="arm_0"/>
    <child link="arm_1"/>
    <limit effort="2.5" lower="-3.14159265359" upper="3.14159265359" velocity="3.00545697193"/>
    <safety_controller k_position="3" k_velocity="1000" soft_lower_limit="-3.14159265359" soft_upper_limit="3.14159265359"/>
    <origin rpy="0 0 0" xyz="0 0 0"/>
    <axis xyz="0 0 1"/>
  </joint>
  <link name="arm_1">
    <!-- For Box Collision Intertial -->
    <collision>
      <origin rpy="0 0 0" xyz="0 0 0"/>
      <geometry>
        <box size="0.054 0.132 0.054"/>
      </geometry>
    </collision>
    <inertial>
      <!-- center of mass -->
      <origin rpy="0 0 0" xyz="0 0 0"/>
      <mass value="0.855"/>
      <!-- box inertia: 1/12*m(y^2+z^2), ... -->
      <inertia ixx="0.001449225" ixy="0" ixz="0" iyy="0.00041553" iyz="0" izz="0.001449225"/>
    </inertial>
    <!-- H54-200-S500 -->
    <visual>
      <origin xyz="0 -0.066 0"/>
      <geometry>
        <mesh filename="package://omni_description/stl/H54-200-S500-R.STL" scale="0.001 0.001 0.001"/>
      </geometry>
      <material name="omni/Red"/>
    </visual>
    <!-- FRP54-A110 -->
    <visual>
      <origin rpy="1.57079632679 0 0" xyz="0 0 -0.033"/>
      <geometry>
        <mesh filename="package://omni_description/stl/FRP54-A110.STL" scale="0.001 0.001 0.001"/>
      </geometry>
      <material name="omni/Red"/>
    </visual>
  </link>
  <joint name="arm_1_2" type="revolute">
    <parent link="arm_1"/>
    <child link="arm_2"/>
    <limit effort="44.7" lower="-1.80159265359" upper="1.79840734641" velocity="3.46622389446"/>
    <safety_controller k_position="3" k_velocity="1000" soft_lower_limit="-1.80159265359" soft_upper_limit="1.79840734641"/>
    <origin rpy="1.57079632679 -1.57079632679 0" xyz="0 0 0"/>
    <axis xyz="0 0 1"/>
  </joint>
  <link name="arm_2">
    <!-- For Box Visual Collision Intertial -->
    <visual>
      <origin rpy="0 0 0" xyz="0.141 0 0"/>
      <geometry name="profile_2">
        <box size="0.18 0.04 0.04"/>
      </geometry>
      <material name="omni/Green"/>
    </visual>
    <collision>
      <origin rpy="0 0 0" xyz="0.141 0 0"/>
      <geometry>
        <box size="0.18 0.04 0.04"/>
      </geometry>
    </collision>
    <inertial>
      <!-- center of mass -->
      <origin rpy="0 0 0" xyz="0.141 0 0"/>
      <mass value="0.2484"/>
      <!-- box inertia: 1/12*m(y^2+z^2), ... -->
      <inertia ixx="6.624e-05" ixy="0" ixz="0" iyy="0.0007038" iyz="0" izz="0.0007038"/>
    </inertial>
    <!-- FRP54-H220 -->
    <visual>
      <origin rpy="0 3.14159265359 -1.57079632679" xyz="0 0 0"/>
      <geometry>
        <mesh filename="package://omni_description/stl/FRP54-H220.STL" scale="0.001 0.001 0.001"/>
      </geometry>
      <material name="omni/Green"/>
    </visual>
    <!-- FRP54-A110 -->
    <visual>
      <origin rpy="0 0 -1.57079632679" xyz="0.231 0 0"/>
      <geometry>
        <mesh filename="package://omni_description/stl/FRP54-A110.STL" scale="0.001 0.001 0.001"/>
      </geometry>
      <material name="omni/Green"/>
    </visual>
  </link>
  <joint name="arm_2_sub" type="fixed">
    <parent link="arm_2"/>
    <child link="arm_2_sub"/>
    <origin xyz="0 0 0"/>
  </joint>
  <link name="arm_2_sub">
    <!-- L5450-S500 -->
    -
            
    <!-- For Box Collision Intertial -->
    <collision>
      <origin rpy="0 0 0" xyz="0.264 0 0"/>
      <geometry>
        <box size="0.054 0.054 0.114"/>
      </geometry>
    </collision>
    <inertial>
      <!-- center of mass -->
      <origin rpy="0 0 0" xyz="0.264 0 0"/>
      <mass value="0.662"/>
      <!-- box inertia: 1/12*m(y^2+z^2), ... -->
      <inertia ixx="0.000877812" ixy="0" ixz="0" iyy="0.000877812" iyz="0" izz="0.000321732"/>
    </inertial>
    <visual>
      <origin rpy="-1.57079632679 0 0" xyz="0.264 0 0.057"/>
      <geometry>
        <mesh filename="package://omni_description/stl/L54-50-S500-R.STL" scale="0.001 0.001 0.001"/>
      </geometry>
      <material name="omni/Green"/>
    </visual>
  </link>
  <joint name="arm_2_3" type="revolute">
    <parent link="arm_2"/>
    <child link="arm_3"/>
    <limit effort="14" lower="-1.82159265359" upper="1.25840734641" velocity="1.67551608191"/>
    <safety_controller k_position="3" k_velocity="1000" soft_lower_limit="-1.82159265359" soft_upper_limit="1.35840734641"/>
    <origin rpy="0 0 -1.57079632679" xyz="0.264 0 0"/>
    <axis xyz="0 0 1"/>
  </joint>
  <link name="arm_3">
    <!-- For Box Visual Collision Intertial -->
    <visual>
      <origin rpy="0 0 0" xyz="0 0.081 0"/>
      <geometry name="profile_3">
        <box size="0.04 0.06 0.04"/>
      </geometry>
      <material name="omni/Yellow"/>
    </visual>
    <collision>
      <origin rpy="0 0 0" xyz="0 0.081 0"/>
      <geometry>
        <box size="0.04 0.06 0.04"/>
      </geometry>
    </collision>
    <inertial>
      <!-- center of mass -->
      <origin rpy="0 0 0" xyz="0 0.081 0"/>
      <mass value="0.0828"/>
      <!-- box inertia: 1/12*m(y^2+z^2), ... -->
      <inertia ixx="3.588e-05" ixy="0" ixz="0" iyy="2.208e-05" iyz="0" izz="3.588e-05"/>
    </inertial>
    <!-- FRP54-H120 -->
    <visual>
      <origin rpy="0 3.14159265359 0" xyz="0 0 0"/>
      <geometry>
        <mesh filename="package://omni_description/stl/FRP54-H120.STL" scale="0.001 0.001 0.001"/>
      </geometry>
      <material name="omni/Yellow"/>
    </visual>
    <!-- FRP54-A110 -->
    <visual>
      <origin rpy="0 0 0" xyz="0 0.111 0"/>
      <geometry>
        <mesh filename="package://omni_description/stl/FRP54-A110.STL" scale="0.001 0.001 0.001"/>
      </geometry>
      <material name="omni/Yellow"/>
    </visual>
  </link>
  <joint name="arm_3_sub" type="fixed">
    <parent link="arm_3"/>
    <child link="arm_3_sub"/>
    <origin xyz="0 0 0"/>
  </joint>
  <link name="arm_3_sub">
    <!-- For Box Collision Intertial -->
    <collision>
      <origin rpy="0 0 0" xyz="0 0.171 0"/>
      <geometry>
        <box size="0.054 0.108 0.054"/>
      </geometry>
    </collision>
    <inertial>
      <!-- center of mass -->
      <origin rpy="0 0 0" xyz="0 0.171 0"/>
      <mass value="0.612"/>
      <!-- box inertia: 1/12*m(y^2+z^2), ... -->
      <inertia ixx="0.00074358" ixy="0" ixz="0" iyy="0.000297432" iyz="0" izz="0.00074358"/>
    </inertial>
    <visual>
      <origin rpy="0 -3.14159265359 0" xyz="0 0.117 0"/>
      <geometry>
        <mesh filename="package://omni_description/stl/L54-30-S500-R.STL" scale="0.001 0.001 0.001"/>
      </geometry>
      <material name="omni/Yellow"/>
    </visual>
  </link>
  <joint name="arm_3_4" type="revolute">
    <parent link="arm_3"/>
    <child link="arm_4"/>
    <limit effort="2.5" lower="-3.14159265359" upper="3.14159265359" velocity="3.00545697193"/>
    <safety_controller k_position="3" k_velocity="1000" soft_lower_limit="-3.14159265359" soft_upper_limit="3.14159265359"/>
    <origin rpy="-1.57079632679 0 0" xyz="0 0.252 0"/>
    <axis xyz="0 0 1"/>
  </joint>
  <link name="arm_4">
    <!-- For Box Collision Intertial -->
    <collision>
      <origin rpy="0 0 0" xyz="0 0.006 0"/>
      <geometry>
        <box size="0.042 0.072 0.042"/>
      </geometry>
    </collision>
    <inertial>
      <!-- center of mass -->
      <origin rpy="0 0 0" xyz="0 0.006 0"/>
      <mass value="0.257"/>
      <!-- box inertia: 1/12*m(y^2+z^2), ... -->
      <inertia ixx="0.000148803" ixy="0" ixz="0" iyy="7.5558e-05" iyz="0" izz="0.000148803"/>
    </inertial>
    <visual>
      <origin rpy="0 0 0" xyz="0 -0.03 0"/>
      <geometry>
        <mesh filename="package://omni_description/stl/L42-10-S300-R.STL" scale="0.001 0.001 0.001"/>
      </geometry>
      <material name="omni/DarkGrey"/>
    </visual>
    <!-- FRP42-A110 -->
    <visual>
      <origin rpy="1.57079632679 0 0" xyz="0 0 -0.027"/>
      <geometry>
        <mesh filename="package://omni_description/stl/FRP42-A110.STL" scale="0.001 0.001 0.001"/>
      </geometry>
      <material name="omni/DarkGrey"/>
    </visual>
  </link>
  <joint name="arm_4_5" type="revolute">
    <parent link="arm_4"/>
    <child link="arm_5"/>
    <limit effort="1.2" lower="-0.942477796077" upper="0.942477796077" velocity="3.11017672705"/>
    <safety_controller k_position="2" k_velocity="1000" soft_lower_limit="-0.942477796077" soft_upper_limit="0.942477796077"/>
    <origin rpy="1.57079632679 0 0" xyz="0 0 0"/>
    <axis xyz="0 0 1"/>
  </joint>
  <link name="arm_5">
    <!-- For Box Collision Intertial -->
    <collision>
      <origin rpy="0 0 0" xyz="0 0.039 -0.006"/>
      <geometry>
        <box size="0.042 0.006 0.082"/>
      </geometry>
    </collision>
    <inertial>
      <!-- center of mass -->
      <origin rpy="0 0 0" xyz="0 0.039 -0.006"/>
      <mass value="0.0857"/>
      <!-- box inertia: 1/12*m(y^2+z^2), ... -->
      <inertia ixx="4.82776666667e-05" ixy="0" ixz="0" iyy="6.06184666667e-05" iyz="0" izz="1.2855e-05"/>
    </inertial>
    <!-- FRP42-H120 -->
    <visual>
      <origin rpy="0 0 0" xyz="0 0 -0.006"/>
      <geometry>
        <mesh filename="package://omni_description/stl/FRP42-H120.STL" scale="0.001 0.001 0.001"/>
      </geometry>
      <material name="omni/Blue"/>
    </visual>
  </link>
  <joint name="arm_5_end" type="fixed">
    <parent link="arm_5"/>
    <child link="arm_link"/>
    <origin xyz="0 0.039 -0.006"/>
  </joint>
  <link name="arm_link"/>
  <joint name="arm_end_versaball" type="fixed">
    <parent link="arm_link"/>
    <child link="versaball_link"/>
    <origin rpy="-1.57079632679 0 0" xyz="0 0.081 0"/>
  </joint>
  <link name="versaball_link"/>
</robot>

