<?xml version="1.0" ?>
<!-- =================================================================================== -->
<!-- |    This document was autogenerated by xacro from partial_arm.xacro              | -->
<!-- |    EDITING THIS FILE BY HAND IS NOT RECOMMENDED                                 | -->
<!-- =================================================================================== -->
<robot name="omnigrasper" xmlns:xacro="http://www.ros.org/wiki/xacro">
  <link name="plate">
    <!-- <xacro:visuals_collisions_arm_0/> -->
    <visual>
      <geometry>
        <box size="0.25 0.25 0.10"/>
      </geometry>
    </visual>
  </link>
  <joint name="plate_arm_0" type="fixed">
    <parent link="plate"/>
    <child link="arm_0"/>
    <origin xyz="0 0 0.141"/>
  </joint>
  <link name="arm_0">
    <!-- <xacro:visuals_collisions_arm_0/> -->
    <visual>
      <geometry>
        <box size="0.05 0.05 0.05"/>
      </geometry>
    </visual>
  </link>
  <joint name="arm_0_1" type="revolute">
    <parent link="arm_0"/>
    <child link="arm_1"/>
    <limit effort="5" lower="-3.14159265359" upper="3.14159265359" velocity="5"/>
    <origin rpy="0 0 0" xyz="0 0 0"/>
    <axis xyz="0 0 1"/>
    <!-- <dynamics damping="${joint_dmp}"/> -->
  </joint>
  <link name="arm_1">
    <visual>
      <geometry>
        <box size="0.054 0.132"/>
      </geometry>
    </visual>
    <!-- TODO Parts to add : frame adaptor FRP54-A110K, idler FRP54-I110 -->
    <inertial>
      <!-- center of mass -->
      <origin rpy="0 0 0" xyz="0 0 33.0"/>
      <mass value="0.855"/>
      <!-- box inertia: 1/12*m(y^2+z^2), ... -->
      <inertia ixx="0.001449225" ixy="0" ixz="0" iyy="0.00041553" iyz="0" izz="0.001449225"/>
    </inertial>
  </link>
  <joint name="arm_1_2" type="revolute">
    <parent link="arm_1"/>
    <child link="arm_2"/>
    <limit effort="5" lower="-2" upper="2" velocity="5"/>
    <origin rpy="-1.57079632679 0 1.57079632679" xyz="0 0 0"/>
    <axis xyz="0 0 1"/>
    <!-- <dynamics damping="${joint_dmp}"/> -->
  </joint>
  <link name="arm_2">
    <visual>
      <geometry name="L54_50_S500">
        <!-- L54-50-S500 -->
        <origin rpy="0 0 0" xyz="264.0 0 0"/>
        <box size="0.054 0.054 0.114"/>
      </geometry>
    </visual>
    <!-- TODO Parts to add : modified (by us) frame FRP54-H220, modified
            (by us) frame adaptor FRP54-H120K (modified by us), idler FRP54-I110 -->
    <inertial>
      <!-- L54-50-S500 -->
      <!-- center of mass -->
      <origin rpy="0 0 0" xyz="264.0 0 0"/>
      <mass value="0.662"/>
      <!-- box inertia: 1/12*m(y^2+z^2), ... -->
      <inertia ixx="0.000877812" ixy="0" ixz="0" iyy="0.000877812" iyz="0" izz="0.000321732"/>
    </inertial>
    <visual>
      <geometry name="profile_2">
        <!-- profile_2 -->
        <origin rpy="0 0 0" xyz="264.0 0 0"/>
        <box size="0.18 0.04 0.04"/>
      </geometry>
    </visual>
    <inertial>
      <!-- aluminium profile -->
      <!-- TODO: take the moments of inertia provided by manufacturer -->
      <!-- center of mass -->
      <origin rpy="0 0 0" xyz="141.0 0 0"/>
      <mass value="0.2484"/>
      <!-- box inertia: 1/12*m(y^2+z^2), ... -->
      <inertia ixx="6.624e-05" ixy="0" ixz="0" iyy="0.0007038" iyz="0" izz="0.0007038"/>
    </inertial>
  </link>
  <!-- TODO use the box link macro in common.xacro -->
</robot>

